[2017-09-14 16:46:42 view.table.model] ERROR 获取 item 数据 ['240000074', '240000069']失败, None
[2017-09-14 16:46:42 view.table.model] ERROR None

[2017-09-14 16:46:44 view.table.model] ERROR 获取 item 数据 ['240000074', '240000069']失败, None
[2017-09-14 16:46:44 view.table.model] ERROR None

[2017-09-14 16:46:45 view.table.model] ERROR 获取 item 数据 ['240000069']失败, None
[2017-09-14 16:46:45 view.table.model] ERROR None

[2017-09-14 16:46:47 view.table.model] ERROR 获取 item 数据 ['240000069']失败, None
[2017-09-14 16:46:47 view.table.model] ERROR None

[2017-09-14 16:46:48 view.table.model] ERROR 获取 item 数据 ['240000074', '240000069']失败, None
[2017-09-14 16:46:48 view.table.model] ERROR None

[2017-09-14 16:46:52 view.table.model] ERROR 获取 item 数据 ['240000069']失败, None
[2017-09-14 16:46:52 view.table.model] ERROR None

[2017-09-14 16:46:52 view.table.model] ERROR 获取 item 数据 ['240000074', '240000069']失败, None
[2017-09-14 16:46:52 view.table.model] ERROR None

[2017-09-14 16:47:15 view.table.model] ERROR 获取 item 数据 ['240000074']失败, None
[2017-09-14 16:47:15 view.table.model] ERROR None

[2017-09-14 16:47:17 view.table.model] ERROR 获取 item 数据 ['240000074']失败, None
[2017-09-14 16:47:17 view.table.model] ERROR None

[2017-09-14 16:47:19 view.table.model] ERROR 获取 item 数据 ['240000069']失败, None
[2017-09-14 16:47:19 view.table.model] ERROR None

[2017-09-14 16:47:20 view.table.model] ERROR 获取 item 数据 ['240000074', '240000069']失败, None
[2017-09-14 16:47:20 view.table.model] ERROR None

[2017-09-14 16:47:34 view.table.model] ERROR 获取 item 数据 ['240000074', '240000069']失败, None
[2017-09-14 16:47:34 view.table.model] ERROR None

[2017-09-14 16:48:38 view.table.model] ERROR 获取 item 数据 ['240000074', '240000069']失败, None
[2017-09-14 16:48:38 view.table.model] ERROR None

[2017-09-19 13:29:26 view.table.model] ERROR select value error: data_type, USER_DEFINE
[2017-09-19 13:29:26 view.table.model] ERROR Traceback (most recent call last):
  File "/Users/zhaojingping/PycharmProjects/AuxiTools/test/OrcTestToolsKit/OrcView/Lib/LibTable.py", line 138, in data
    return self._definition.select_def[_field.id][_value]
KeyError: u'USER_DEFINE'

[2017-09-19 13:29:26 view.table.model] ERROR select value error: data_type, USER_DEFINE
[2017-09-19 13:29:26 view.table.model] ERROR Traceback (most recent call last):
  File "/Users/zhaojingping/PycharmProjects/AuxiTools/test/OrcTestToolsKit/OrcView/Lib/LibTable.py", line 138, in data
    return self._definition.select_def[_field.id][_value]
KeyError: u'USER_DEFINE'

[2017-09-19 13:29:26 view.table.model] ERROR select value error: data_type, USER_DEFINE
[2017-09-19 13:29:26 view.table.model] ERROR Traceback (most recent call last):
  File "/Users/zhaojingping/PycharmProjects/AuxiTools/test/OrcTestToolsKit/OrcView/Lib/LibTable.py", line 138, in data
    return self._definition.select_def[_field.id][_value]
KeyError: u'USER_DEFINE'

[2017-09-19 13:29:26 view.table.model] ERROR select value error: data_type, USER_DEFINE
[2017-09-19 13:29:26 view.table.model] ERROR Traceback (most recent call last):
  File "/Users/zhaojingping/PycharmProjects/AuxiTools/test/OrcTestToolsKit/OrcView/Lib/LibTable.py", line 138, in data
    return self._definition.select_def[_field.id][_value]
KeyError: u'USER_DEFINE'

[2017-09-19 13:29:27 view.table.model] ERROR select value error: data_type, USER_DEFINE
[2017-09-19 13:29:27 view.table.model] ERROR Traceback (most recent call last):
  File "/Users/zhaojingping/PycharmProjects/AuxiTools/test/OrcTestToolsKit/OrcView/Lib/LibTable.py", line 138, in data
    return self._definition.select_def[_field.id][_value]
KeyError: u'USER_DEFINE'

[2017-09-19 13:29:27 view.table.model] ERROR select value error: data_type, USER_DEFINE
[2017-09-19 13:29:27 view.table.model] ERROR Traceback (most recent call last):
  File "/Users/zhaojingping/PycharmProjects/AuxiTools/test/OrcTestToolsKit/OrcView/Lib/LibTable.py", line 138, in data
    return self._definition.select_def[_field.id][_value]
KeyError: u'USER_DEFINE'

[2017-09-19 13:29:27 view.table.model] ERROR select value error: data_type, USER_DEFINE
[2017-09-19 13:29:27 view.table.model] ERROR Traceback (most recent call last):
  File "/Users/zhaojingping/PycharmProjects/AuxiTools/test/OrcTestToolsKit/OrcView/Lib/LibTable.py", line 138, in data
    return self._definition.select_def[_field.id][_value]
KeyError: u'USER_DEFINE'

[2017-09-19 13:29:27 view.table.model] ERROR select value error: data_type, USER_DEFINE
[2017-09-19 13:29:27 view.table.model] ERROR Traceback (most recent call last):
  File "/Users/zhaojingping/PycharmProjects/AuxiTools/test/OrcTestToolsKit/OrcView/Lib/LibTable.py", line 138, in data
    return self._definition.select_def[_field.id][_value]
KeyError: u'USER_DEFINE'

[2017-09-19 13:29:27 view.table.model] ERROR select value error: data_type, USER_DEFINE
[2017-09-19 13:29:27 view.table.model] ERROR Traceback (most recent call last):
  File "/Users/zhaojingping/PycharmProjects/AuxiTools/test/OrcTestToolsKit/OrcView/Lib/LibTable.py", line 138, in data
    return self._definition.select_def[_field.id][_value]
KeyError: u'USER_DEFINE'

[2017-09-19 13:29:27 view.table.model] ERROR select value error: data_type, USER_DEFINE
[2017-09-19 13:29:27 view.table.model] ERROR Traceback (most recent call last):
  File "/Users/zhaojingping/PycharmProjects/AuxiTools/test/OrcTestToolsKit/OrcView/Lib/LibTable.py", line 138, in data
    return self._definition.select_def[_field.id][_value]
KeyError: u'USER_DEFINE'

[2017-09-19 13:29:27 view.table.model] ERROR select value error: data_type, USER_DEFINE
[2017-09-19 13:29:27 view.table.model] ERROR Traceback (most recent call last):
  File "/Users/zhaojingping/PycharmProjects/AuxiTools/test/OrcTestToolsKit/OrcView/Lib/LibTable.py", line 138, in data
    return self._definition.select_def[_field.id][_value]
KeyError: u'USER_DEFINE'

[2017-09-19 13:29:27 view.table.model] ERROR select value error: data_type, USER_DEFINE
[2017-09-19 13:29:27 view.table.model] ERROR Traceback (most recent call last):
  File "/Users/zhaojingping/PycharmProjects/AuxiTools/test/OrcTestToolsKit/OrcView/Lib/LibTable.py", line 138, in data
    return self._definition.select_def[_field.id][_value]
KeyError: u'USER_DEFINE'

[2017-09-19 13:29:33 view.table.model] ERROR select value error: data_type, USER_DEFINE
[2017-09-19 13:29:33 view.table.model] ERROR Traceback (most recent call last):
  File "/Users/zhaojingping/PycharmProjects/AuxiTools/test/OrcTestToolsKit/OrcView/Lib/LibTable.py", line 138, in data
    return self._definition.select_def[_field.id][_value]
KeyError: u'USER_DEFINE'

[2017-09-19 13:29:33 view.table.model] ERROR select value error: data_type, USER_DEFINE
[2017-09-19 13:29:33 view.table.model] ERROR Traceback (most recent call last):
  File "/Users/zhaojingping/PycharmProjects/AuxiTools/test/OrcTestToolsKit/OrcView/Lib/LibTable.py", line 138, in data
    return self._definition.select_def[_field.id][_value]
KeyError: u'USER_DEFINE'

[2017-09-19 13:29:33 view.table.model] ERROR select value error: data_type, USER_DEFINE
[2017-09-19 13:29:33 view.table.model] ERROR Traceback (most recent call last):
  File "/Users/zhaojingping/PycharmProjects/AuxiTools/test/OrcTestToolsKit/OrcView/Lib/LibTable.py", line 138, in data
    return self._definition.select_def[_field.id][_value]
KeyError: u'USER_DEFINE'

[2017-09-19 13:29:33 view.table.model] ERROR select value error: data_type, USER_DEFINE
[2017-09-19 13:29:33 view.table.model] ERROR Traceback (most recent call last):
  File "/Users/zhaojingping/PycharmProjects/AuxiTools/test/OrcTestToolsKit/OrcView/Lib/LibTable.py", line 138, in data
    return self._definition.select_def[_field.id][_value]
KeyError: u'USER_DEFINE'

[2017-09-19 13:29:34 view.table.model] ERROR select value error: data_type, USER_DEFINE
[2017-09-19 13:29:34 view.table.model] ERROR Traceback (most recent call last):
  File "/Users/zhaojingping/PycharmProjects/AuxiTools/test/OrcTestToolsKit/OrcView/Lib/LibTable.py", line 138, in data
    return self._definition.select_def[_field.id][_value]
KeyError: u'USER_DEFINE'

